<?xml version='1.0' encoding='utf-8'?>
<robot name="tiago_pro_right_arm" xmlns:xacro="http://www.ros.org/wiki/xacro">
  <link name="torso_lift_link">
    <inertial>
      <origin rpy="0 0 0" xyz="0 0 0" />
      <mass value="3.2426605225" />
      <inertia ixx="0.0295505132526159" ixy="-8.45037675389904E-07" ixz="-8.18202394725631E-09" iyy="0.0170989464968443" iyz="-8.17597174318507E-06" izz="0.0289920549839735" />
    </inertial>
    <visual>
      <geometry>
        <mesh filename="package://meshes/torso_lift_link.stl" scale="1 1 1" />
      </geometry>
      <material name="rgba-0.894117647058823-0.913725490196078-0.929411764705882-1">
        <color rgba="0.8941 0.9137 0.9294 1" />
      </material>
    </visual>
    <collision>
      <geometry>
        <mesh filename="package://meshes/torso_lift_link_collision.stl" scale="1 1 1" />
      </geometry>
    </collision>
    <collision>
      <origin rpy="0 0 -1.570796" xyz="-0.226436 3.1E-05 0.00524" />
      <geometry>
        <mesh filename="package://meshes/laptop_tray_collision.stl" scale="1 1 1" />
      </geometry>
    </collision>
  </link>
  <link name="arm_right_1_link">
    <inertial>
      <origin rpy="0 0 0" xyz="0.004392 0.016184 0.15576" />
      <mass value="1.1325000525" />
      <inertia ixx="0.00255136331543326" ixy="9.48840352066327E-06" ixz="6.46017069811933E-05" iyy="0.00234987353906035" iyz="-0.000206586526473984" izz="0.000971474219113588" />
    </inertial>
    <visual>
      <geometry>
        <mesh filename="package://meshes/arm_1_link.stl" scale="1 1 1" />
      </geometry>
      <material name="DarkGrey">
        <color rgba="0.102 0.102 0.102 1" />
      </material>
    </visual>
    <collision>
      <geometry>
        <mesh filename="package://meshes/arm_1_link_collision.stl" scale="1 1 1" />
      </geometry>
    </collision>
  </link>
  <link name="arm_right_2_link">
    <inertial>
      <origin rpy="0 0 0" xyz="0.01786 -0.11956 -0.032097" />
      <mass value="1.0435999632" />
      <inertia ixx="0.0015021002618596" ixy="0.000112640009319875" ixz="1.06919778772863E-05" iyy="0.000880169856827706" iyz="-0.000158429975272156" izz="0.00160209974274039" />
    </inertial>
    <visual>
      <geometry>
        <mesh filename="package://meshes/arm_2_link.stl" scale="1 1 1" />
      </geometry>
      <material name="DarkGrey">
        <color rgba="0.102 0.102 0.102 1" />
      </material>
    </visual>
    <collision>
      <geometry>
        <mesh filename="package://meshes/arm_2_link_collision.stl" scale="1 1 1" />
      </geometry>
    </collision>
  </link>
  <link name="arm_right_3_link">
    <inertial>
      <origin rpy="0 0 0" xyz="0.016184 -0.004392 0.13565" />
      <mass value="1.1325000525" />
      <inertia ixx="0.00234988471493125" ixy="-1.01885489129927E-05" ixz="-0.000206559052458033" iyy="0.00255136005580425" iyz="-6.44990432192571E-05" izz="0.000971465953625739" />
    </inertial>
    <visual>
      <geometry>
        <mesh filename="package://meshes/arm_3_link.stl" scale="1 1 1" />
      </geometry>
      <material name="DarkGrey">
        <color rgba="0.102 0.102 0.102 1" />
      </material>
    </visual>
    <collision>
      <geometry>
        <mesh filename="package://meshes/arm_3_link_collision.stl" scale="1 1 1" />
      </geometry>
    </collision>
  </link>
  <link name="arm_right_4_link">
    <inertial>
      <origin rpy="0 0 0" xyz="-0.01786 0.11956 -0.032097" />
      <mass value="1.0435999632" />
      <inertia ixx="0.0015021002618596" ixy="0.00011263999476796" ixz="-1.06920688267564E-05" iyy="0.000880169856827706" iyz="0.000158429975272156" izz="0.00160209985915571" />
    </inertial>
    <visual>
      <geometry>
        <mesh filename="package://meshes/arm_4_link.stl" scale="1 1 1" />
      </geometry>
      <material name="DarkGrey">
        <color rgba="0.102 0.102 0.102 1" />
      </material>
    </visual>
    <collision>
      <geometry>
        <mesh filename="package://meshes/arm_4_link_collision.stl" scale="1 1 1" />
      </geometry>
    </collision>
  </link>
  <link name="arm_right_5_link">
    <inertial>
      <origin rpy="0 0 0" xyz="-0.00017 -0.02738 0.06749" />
      <mass value="0.3129799962" />
      <inertia ixx="0.00157000008039176" ixy="-1.82568543616313E-10" ixz="-8.27204832409834E-11" iyy="0.00154000089969486" iyz="-0.000380000419681892" izz="0.000430000334745273" />
    </inertial>
    <visual>
      <geometry>
        <mesh filename="package://meshes/arm_5_link.stl" scale="1 1 1" />
      </geometry>
      <material name="DarkGrey">
        <color rgba="0.102 0.102 0.102 1" />
      </material>
    </visual>
    <collision>
      <geometry>
        <mesh filename="package://meshes/arm_5_link_collision.stl" scale="1 1 1" />
      </geometry>
    </collision>
  </link>
  <link name="arm_right_6_link">
    <inertial>
      <origin rpy="0 0 0" xyz="0.031765 -0.006515 -0.040805" />
      <mass value="1.3458735943" />
      <inertia ixx="0.00109877821523696" ixy="0.000130027096020058" ixz="-2.94245683107874E-06" iyy="0.00116513588000089" iyz="4.19828938902356E-06" izz="0.00118972675409168" />
    </inertial>
    <visual>
      <geometry>
        <mesh filename="package://meshes/arm_6_link.stl" scale="1 1 1" />
      </geometry>
      <material name="DarkGrey">
        <color rgba="0.102 0.102 0.102 1" />
      </material>
    </visual>
    <collision>
      <geometry>
        <mesh filename="package://meshes/arm_6_link_collision.stl" scale="1 1 1" />
      </geometry>
    </collision>
  </link>
  <link name="arm_right_7_link">
    <inertial>
      <origin rpy="0 0 0" xyz="0.00174 -0.00223 0.0083" />
      <mass value="0.1239899993" />
      <inertia ixx="7.999999797903E-05" ixy="0" ixz="0" iyy="5.99999948462937E-05" iyz="0" izz="0.000119999989692587" />
    </inertial>
    <visual>
      <geometry>
        <mesh filename="package://meshes/arm_7_link.stl" scale="1 1 1" />
      </geometry>
      <material name="DarkGrey">
        <color rgba="0.102 0.102 0.102 1" />
      </material>
    </visual>
    <collision>
      <geometry>
        <cylinder length="0.0366" radius="0.0375" />
      </geometry>
    </collision>
  </link>
  <link name="arm_right_tool_link" />
  <joint name="arm_right_1_joint" type="revolute">
    <origin rpy="-2.0679 0 -1.91989" xyz="0.08976 -0.15918 -0.092008" />
    <parent link="torso_lift_link" />
    <child link="arm_right_1_link" />
    <axis xyz="0 0 1" />
    <dynamics damping="1" friction="1" />
    <limit lower="-4.7123889438808" upper="0.523598771542311" effort="43" velocity="2.5" />
  </joint>
  <joint name="arm_right_2_joint" type="revolute">
    <origin rpy="-1.570796 0 -1.570796" xyz="0.03711 0.02 0.18" />
    <parent link="arm_right_1_link" />
    <child link="arm_right_2_link" />
    <axis xyz="0 0 1" />
    <dynamics damping="1" friction="1" />
    <limit lower="-2.44346093386412" upper="1.13446400500834" effort="43" velocity="2.5" />
  </joint>
  <joint name="arm_right_3_joint" type="revolute">
    <origin rpy="-4.712389 0 0" xyz="0.02 -0.17011 -0.03711" />
    <parent link="arm_right_2_link" />
    <child link="arm_right_3_link" />
    <axis xyz="0 0 1" />
    <dynamics damping="1" friction="1" />
    <limit lower="-2.61799385771155" upper="2.61799385771155" effort="26" velocity="2.5" />
  </joint>
  <joint name="arm_right_4_joint" type="revolute">
    <origin rpy="-4.712389 0 0" xyz="0.02 -0.03711 0.15989" />
    <parent link="arm_right_3_link" />
    <child link="arm_right_4_link" />
    <axis xyz="0 0 1" />
    <dynamics damping="1" friction="1" />
    <limit lower="-2.44346093386412" upper="1.13446400500834" effort="26" velocity="2.5" />
  </joint>
  <joint name="arm_right_5_joint" type="revolute">
    <origin rpy="-4.712389 0.001593 -3.141593" xyz="-0.02 0.17011 -0.03711" />
    <parent link="arm_right_4_link" />
    <child link="arm_right_5_link" />
    <axis xyz="0 0 1" />
    <dynamics damping="1" friction="1" />
    <limit lower="-1.57079631462693" upper="3.66519140079618" effort="26" velocity="2.5" />
  </joint>
  <joint name="arm_right_6_joint" type="revolute">
    <origin rpy="-1.5708 0 -3.143185" xyz="0 -0.0422 0.1654" />
    <parent link="arm_right_5_link" />
    <child link="arm_right_6_link" />
    <axis xyz="0 0 -1" />
    <dynamics damping="1" friction="1" />
    <limit lower="-1.88495557755232" upper="3.00196629017591" effort="26" velocity="2.5" />
  </joint>
  <joint name="arm_right_7_joint" type="revolute">
    <origin rpy="-4.712385 0 0" xyz="0.07 -0.053401 -0.0422" />
    <parent link="arm_right_6_link" />
    <child link="arm_right_7_link" />
    <axis xyz="0 0 1" />
    <dynamics damping="1" friction="1" />
    <limit lower="-2.61799385771155" upper="2.61799385771155" effort="26" velocity="2.5" />
  </joint>
  <joint name="arm_right_tool_joint" type="fixed">
    <origin xyz="0 0 0.017001" rpy="0 0 0" />
    <parent link="arm_right_7_link" />
    <child link="arm_right_tool_link" />
  </joint>
</robot>